Traceback (most recent call last):
  File "/Users/shishengli/anaconda3/lib/python3.11/site-packages/jupyter_cache/executors/utils.py", line 58, in single_nb_execution
    executenb(
  File "/Users/shishengli/anaconda3/lib/python3.11/site-packages/nbclient/client.py", line 1204, in execute
    return NotebookClient(nb=nb, resources=resources, km=km, **kwargs).execute()
           ^^^^^^^^^^^^^^^^^^^^^^^^^^^^^^^^^^^^^^^^^^^^^^^^^^^^^^^^^^^^^^^^^^^^^
  File "/Users/shishengli/anaconda3/lib/python3.11/site-packages/nbclient/util.py", line 84, in wrapped
    return just_run(coro(*args, **kwargs))
           ^^^^^^^^^^^^^^^^^^^^^^^^^^^^^^^
  File "/Users/shishengli/anaconda3/lib/python3.11/site-packages/nbclient/util.py", line 62, in just_run
    return loop.run_until_complete(coro)
           ^^^^^^^^^^^^^^^^^^^^^^^^^^^^^
  File "/Users/shishengli/anaconda3/lib/python3.11/asyncio/base_events.py", line 653, in run_until_complete
    return future.result()
           ^^^^^^^^^^^^^^^
  File "/Users/shishengli/anaconda3/lib/python3.11/site-packages/nbclient/client.py", line 663, in async_execute
    await self.async_execute_cell(
  File "/Users/shishengli/anaconda3/lib/python3.11/site-packages/nbclient/client.py", line 965, in async_execute_cell
    await self._check_raise_for_error(cell, cell_index, exec_reply)
  File "/Users/shishengli/anaconda3/lib/python3.11/site-packages/nbclient/client.py", line 862, in _check_raise_for_error
    raise CellExecutionError.from_cell_and_msg(cell, exec_reply_content)
nbclient.exceptions.CellExecutionError: An error occurred while executing the following cell:
------------------
import requests, jwt, time
import json

jwt_secret_fn = '/etc/sg-a-jwt.hex'
with open(jwt_secret_fn, 'r') as f:
    jwt_secret = f.read().strip()
assert len(jwt_secret) == 64
jwt_secret_bytes = bytes.fromhex(jwt_secret)
assert len(jwt_secret_bytes) == 32

def print_obj(obj):
    print(json.dumps(obj, indent=2))

def call_engine_api(payload):
    global jwt_secret_bytes

    jwt_payload = {
        "iat": int(time.time()),
    }
    jwt_token = jwt.encode(jwt_payload, jwt_secret_bytes, algorithm='HS256')

    engine_api_endpoint = 'http://localhost:8551'

    x = requests.request('POST', engine_api_endpoint, json=payload, headers={
        'Authorization': 'Bearer ' + jwt_token,
        'Content-Type': 'application/json',
    })

    obj = json.loads(x.text)
    #print_obj(obj)
    assert obj["jsonrpc"] == "2.0"

    return obj

# test call
ret = call_engine_api({
    "jsonrpc": "2.0",
    "method": "eth_blockNumber",
    "params": [],
    "id": 1,
})
blocknumber = int(ret["result"], 0)
assert blocknumber > 0
print(f"bloknumber is {blocknumber}")
------------------

[0;31m---------------------------------------------------------------------------[0m
[0;31mConnectionRefusedError[0m                    Traceback (most recent call last)
File [0;32m~/anaconda3/lib/python3.11/site-packages/urllib3/connection.py:174[0m, in [0;36mHTTPConnection._new_conn[0;34m(self)[0m
[1;32m    173[0m [38;5;28;01mtry[39;00m:
[0;32m--> 174[0m     conn [38;5;241m=[39m connection[38;5;241m.[39mcreate_connection(
[1;32m    175[0m         ([38;5;28mself[39m[38;5;241m.[39m_dns_host, [38;5;28mself[39m[38;5;241m.[39mport), [38;5;28mself[39m[38;5;241m.[39mtimeout, [38;5;241m*[39m[38;5;241m*[39mextra_kw
[1;32m    176[0m     )
[1;32m    178[0m [38;5;28;01mexcept[39;00m SocketTimeout:

File [0;32m~/anaconda3/lib/python3.11/site-packages/urllib3/util/connection.py:95[0m, in [0;36mcreate_connection[0;34m(address, timeout, source_address, socket_options)[0m
[1;32m     94[0m [38;5;28;01mif[39;00m err [38;5;129;01mis[39;00m [38;5;129;01mnot[39;00m [38;5;28;01mNone[39;00m:
[0;32m---> 95[0m     [38;5;28;01mraise[39;00m err
[1;32m     97[0m [38;5;28;01mraise[39;00m socket[38;5;241m.[39merror([38;5;124m"[39m[38;5;124mgetaddrinfo returns an empty list[39m[38;5;124m"[39m)

File [0;32m~/anaconda3/lib/python3.11/site-packages/urllib3/util/connection.py:85[0m, in [0;36mcreate_connection[0;34m(address, timeout, source_address, socket_options)[0m
[1;32m     84[0m     sock[38;5;241m.[39mbind(source_address)
[0;32m---> 85[0m sock[38;5;241m.[39mconnect(sa)
[1;32m     86[0m [38;5;28;01mreturn[39;00m sock

[0;31mConnectionRefusedError[0m: [Errno 61] Connection refused

During handling of the above exception, another exception occurred:

[0;31mNewConnectionError[0m                        Traceback (most recent call last)
File [0;32m~/anaconda3/lib/python3.11/site-packages/urllib3/connectionpool.py:714[0m, in [0;36mHTTPConnectionPool.urlopen[0;34m(self, method, url, body, headers, retries, redirect, assert_same_host, timeout, pool_timeout, release_conn, chunked, body_pos, **response_kw)[0m
[1;32m    713[0m [38;5;66;03m# Make the request on the httplib connection object.[39;00m
[0;32m--> 714[0m httplib_response [38;5;241m=[39m [38;5;28mself[39m[38;5;241m.[39m_make_request(
[1;32m    715[0m     conn,
[1;32m    716[0m     method,
[1;32m    717[0m     url,
[1;32m    718[0m     timeout[38;5;241m=[39mtimeout_obj,
[1;32m    719[0m     body[38;5;241m=[39mbody,
[1;32m    720[0m     headers[38;5;241m=[39mheaders,
[1;32m    721[0m     chunked[38;5;241m=[39mchunked,
[1;32m    722[0m )
[1;32m    724[0m [38;5;66;03m# If we're going to release the connection in ``finally:``, then[39;00m
[1;32m    725[0m [38;5;66;03m# the response doesn't need to know about the connection. Otherwise[39;00m
[1;32m    726[0m [38;5;66;03m# it will also try to release it and we'll have a double-release[39;00m
[1;32m    727[0m [38;5;66;03m# mess.[39;00m

File [0;32m~/anaconda3/lib/python3.11/site-packages/urllib3/connectionpool.py:415[0m, in [0;36mHTTPConnectionPool._make_request[0;34m(self, conn, method, url, timeout, chunked, **httplib_request_kw)[0m
[1;32m    414[0m     [38;5;28;01melse[39;00m:
[0;32m--> 415[0m         conn[38;5;241m.[39mrequest(method, url, [38;5;241m*[39m[38;5;241m*[39mhttplib_request_kw)
[1;32m    417[0m [38;5;66;03m# We are swallowing BrokenPipeError (errno.EPIPE) since the server is[39;00m
[1;32m    418[0m [38;5;66;03m# legitimately able to close the connection after sending a valid response.[39;00m
[1;32m    419[0m [38;5;66;03m# With this behaviour, the received response is still readable.[39;00m

File [0;32m~/anaconda3/lib/python3.11/site-packages/urllib3/connection.py:244[0m, in [0;36mHTTPConnection.request[0;34m(self, method, url, body, headers)[0m
[1;32m    243[0m     headers[[38;5;124m"[39m[38;5;124mUser-Agent[39m[38;5;124m"[39m] [38;5;241m=[39m _get_default_user_agent()
[0;32m--> 244[0m [38;5;28msuper[39m(HTTPConnection, [38;5;28mself[39m)[38;5;241m.[39mrequest(method, url, body[38;5;241m=[39mbody, headers[38;5;241m=[39mheaders)

File [0;32m~/anaconda3/lib/python3.11/http/client.py:1286[0m, in [0;36mHTTPConnection.request[0;34m(self, method, url, body, headers, encode_chunked)[0m
[1;32m   1285[0m [38;5;250m[39m[38;5;124;03m"""Send a complete request to the server."""[39;00m
[0;32m-> 1286[0m [38;5;28mself[39m[38;5;241m.[39m_send_request(method, url, body, headers, encode_chunked)

File [0;32m~/anaconda3/lib/python3.11/http/client.py:1332[0m, in [0;36mHTTPConnection._send_request[0;34m(self, method, url, body, headers, encode_chunked)[0m
[1;32m   1331[0m     body [38;5;241m=[39m _encode(body, [38;5;124m'[39m[38;5;124mbody[39m[38;5;124m'[39m)
[0;32m-> 1332[0m [38;5;28mself[39m[38;5;241m.[39mendheaders(body, encode_chunked[38;5;241m=[39mencode_chunked)

File [0;32m~/anaconda3/lib/python3.11/http/client.py:1281[0m, in [0;36mHTTPConnection.endheaders[0;34m(self, message_body, encode_chunked)[0m
[1;32m   1280[0m     [38;5;28;01mraise[39;00m CannotSendHeader()
[0;32m-> 1281[0m [38;5;28mself[39m[38;5;241m.[39m_send_output(message_body, encode_chunked[38;5;241m=[39mencode_chunked)

File [0;32m~/anaconda3/lib/python3.11/http/client.py:1041[0m, in [0;36mHTTPConnection._send_output[0;34m(self, message_body, encode_chunked)[0m
[1;32m   1040[0m [38;5;28;01mdel[39;00m [38;5;28mself[39m[38;5;241m.[39m_buffer[:]
[0;32m-> 1041[0m [38;5;28mself[39m[38;5;241m.[39msend(msg)
[1;32m   1043[0m [38;5;28;01mif[39;00m message_body [38;5;129;01mis[39;00m [38;5;129;01mnot[39;00m [38;5;28;01mNone[39;00m:
[1;32m   1044[0m 
[1;32m   1045[0m     [38;5;66;03m# create a consistent interface to message_body[39;00m

File [0;32m~/anaconda3/lib/python3.11/http/client.py:979[0m, in [0;36mHTTPConnection.send[0;34m(self, data)[0m
[1;32m    978[0m [38;5;28;01mif[39;00m [38;5;28mself[39m[38;5;241m.[39mauto_open:
[0;32m--> 979[0m     [38;5;28mself[39m[38;5;241m.[39mconnect()
[1;32m    980[0m [38;5;28;01melse[39;00m:

File [0;32m~/anaconda3/lib/python3.11/site-packages/urllib3/connection.py:205[0m, in [0;36mHTTPConnection.connect[0;34m(self)[0m
[1;32m    204[0m [38;5;28;01mdef[39;00m [38;5;21mconnect[39m([38;5;28mself[39m):
[0;32m--> 205[0m     conn [38;5;241m=[39m [38;5;28mself[39m[38;5;241m.[39m_new_conn()
[1;32m    206[0m     [38;5;28mself[39m[38;5;241m.[39m_prepare_conn(conn)

File [0;32m~/anaconda3/lib/python3.11/site-packages/urllib3/connection.py:186[0m, in [0;36mHTTPConnection._new_conn[0;34m(self)[0m
[1;32m    185[0m [38;5;28;01mexcept[39;00m SocketError [38;5;28;01mas[39;00m e:
[0;32m--> 186[0m     [38;5;28;01mraise[39;00m NewConnectionError(
[1;32m    187[0m         [38;5;28mself[39m, [38;5;124m"[39m[38;5;124mFailed to establish a new connection: [39m[38;5;132;01m%s[39;00m[38;5;124m"[39m [38;5;241m%[39m e
[1;32m    188[0m     )
[1;32m    190[0m [38;5;28;01mreturn[39;00m conn

[0;31mNewConnectionError[0m: <urllib3.connection.HTTPConnection object at 0x117cadf50>: Failed to establish a new connection: [Errno 61] Connection refused

During handling of the above exception, another exception occurred:

[0;31mMaxRetryError[0m                             Traceback (most recent call last)
File [0;32m~/anaconda3/lib/python3.11/site-packages/requests/adapters.py:486[0m, in [0;36mHTTPAdapter.send[0;34m(self, request, stream, timeout, verify, cert, proxies)[0m
[1;32m    485[0m [38;5;28;01mtry[39;00m:
[0;32m--> 486[0m     resp [38;5;241m=[39m conn[38;5;241m.[39murlopen(
[1;32m    487[0m         method[38;5;241m=[39mrequest[38;5;241m.[39mmethod,
[1;32m    488[0m         url[38;5;241m=[39murl,
[1;32m    489[0m         body[38;5;241m=[39mrequest[38;5;241m.[39mbody,
[1;32m    490[0m         headers[38;5;241m=[39mrequest[38;5;241m.[39mheaders,
[1;32m    491[0m         redirect[38;5;241m=[39m[38;5;28;01mFalse[39;00m,
[1;32m    492[0m         assert_same_host[38;5;241m=[39m[38;5;28;01mFalse[39;00m,
[1;32m    493[0m         preload_content[38;5;241m=[39m[38;5;28;01mFalse[39;00m,
[1;32m    494[0m         decode_content[38;5;241m=[39m[38;5;28;01mFalse[39;00m,
[1;32m    495[0m         retries[38;5;241m=[39m[38;5;28mself[39m[38;5;241m.[39mmax_retries,
[1;32m    496[0m         timeout[38;5;241m=[39mtimeout,
[1;32m    497[0m         chunked[38;5;241m=[39mchunked,
[1;32m    498[0m     )
[1;32m    500[0m [38;5;28;01mexcept[39;00m (ProtocolError, [38;5;167;01mOSError[39;00m) [38;5;28;01mas[39;00m err:

File [0;32m~/anaconda3/lib/python3.11/site-packages/urllib3/connectionpool.py:798[0m, in [0;36mHTTPConnectionPool.urlopen[0;34m(self, method, url, body, headers, retries, redirect, assert_same_host, timeout, pool_timeout, release_conn, chunked, body_pos, **response_kw)[0m
[1;32m    796[0m     e [38;5;241m=[39m ProtocolError([38;5;124m"[39m[38;5;124mConnection aborted.[39m[38;5;124m"[39m, e)
[0;32m--> 798[0m retries [38;5;241m=[39m retries[38;5;241m.[39mincrement(
[1;32m    799[0m     method, url, error[38;5;241m=[39me, _pool[38;5;241m=[39m[38;5;28mself[39m, _stacktrace[38;5;241m=[39msys[38;5;241m.[39mexc_info()[[38;5;241m2[39m]
[1;32m    800[0m )
[1;32m    801[0m retries[38;5;241m.[39msleep()

File [0;32m~/anaconda3/lib/python3.11/site-packages/urllib3/util/retry.py:592[0m, in [0;36mRetry.increment[0;34m(self, method, url, response, error, _pool, _stacktrace)[0m
[1;32m    591[0m [38;5;28;01mif[39;00m new_retry[38;5;241m.[39mis_exhausted():
[0;32m--> 592[0m     [38;5;28;01mraise[39;00m MaxRetryError(_pool, url, error [38;5;129;01mor[39;00m ResponseError(cause))
[1;32m    594[0m log[38;5;241m.[39mdebug([38;5;124m"[39m[38;5;124mIncremented Retry for (url=[39m[38;5;124m'[39m[38;5;132;01m%s[39;00m[38;5;124m'[39m[38;5;124m): [39m[38;5;132;01m%r[39;00m[38;5;124m"[39m, url, new_retry)

[0;31mMaxRetryError[0m: HTTPConnectionPool(host='localhost', port=8551): Max retries exceeded with url: / (Caused by NewConnectionError('<urllib3.connection.HTTPConnection object at 0x117cadf50>: Failed to establish a new connection: [Errno 61] Connection refused'))

During handling of the above exception, another exception occurred:

[0;31mConnectionError[0m                           Traceback (most recent call last)
Cell [0;32mIn[1], line 36[0m
[1;32m     33[0m     [38;5;28;01mreturn[39;00m obj
[1;32m     35[0m [38;5;66;03m# test call[39;00m
[0;32m---> 36[0m ret [38;5;241m=[39m call_engine_api({
[1;32m     37[0m     [38;5;124m"[39m[38;5;124mjsonrpc[39m[38;5;124m"[39m: [38;5;124m"[39m[38;5;124m2.0[39m[38;5;124m"[39m,
[1;32m     38[0m     [38;5;124m"[39m[38;5;124mmethod[39m[38;5;124m"[39m: [38;5;124m"[39m[38;5;124meth_blockNumber[39m[38;5;124m"[39m,
[1;32m     39[0m     [38;5;124m"[39m[38;5;124mparams[39m[38;5;124m"[39m: [],
[1;32m     40[0m     [38;5;124m"[39m[38;5;124mid[39m[38;5;124m"[39m: [38;5;241m1[39m,
[1;32m     41[0m })
[1;32m     42[0m blocknumber [38;5;241m=[39m [38;5;28mint[39m(ret[[38;5;124m"[39m[38;5;124mresult[39m[38;5;124m"[39m], [38;5;241m0[39m)
[1;32m     43[0m [38;5;28;01massert[39;00m blocknumber [38;5;241m>[39m [38;5;241m0[39m

Cell [0;32mIn[1], line 24[0m, in [0;36mcall_engine_api[0;34m(payload)[0m
[1;32m     20[0m jwt_token [38;5;241m=[39m jwt[38;5;241m.[39mencode(jwt_payload, jwt_secret_bytes, algorithm[38;5;241m=[39m[38;5;124m'[39m[38;5;124mHS256[39m[38;5;124m'[39m)
[1;32m     22[0m engine_api_endpoint [38;5;241m=[39m [38;5;124m'[39m[38;5;124mhttp://localhost:8551[39m[38;5;124m'[39m
[0;32m---> 24[0m x [38;5;241m=[39m requests[38;5;241m.[39mrequest([38;5;124m'[39m[38;5;124mPOST[39m[38;5;124m'[39m, engine_api_endpoint, json[38;5;241m=[39mpayload, headers[38;5;241m=[39m{
[1;32m     25[0m     [38;5;124m'[39m[38;5;124mAuthorization[39m[38;5;124m'[39m: [38;5;124m'[39m[38;5;124mBearer [39m[38;5;124m'[39m [38;5;241m+[39m jwt_token,
[1;32m     26[0m     [38;5;124m'[39m[38;5;124mContent-Type[39m[38;5;124m'[39m: [38;5;124m'[39m[38;5;124mapplication/json[39m[38;5;124m'[39m,
[1;32m     27[0m })
[1;32m     29[0m obj [38;5;241m=[39m json[38;5;241m.[39mloads(x[38;5;241m.[39mtext)
[1;32m     30[0m [38;5;66;03m#print_obj(obj)[39;00m

File [0;32m~/anaconda3/lib/python3.11/site-packages/requests/api.py:59[0m, in [0;36mrequest[0;34m(method, url, **kwargs)[0m
[1;32m     55[0m [38;5;66;03m# By using the 'with' statement we are sure the session is closed, thus we[39;00m
[1;32m     56[0m [38;5;66;03m# avoid leaving sockets open which can trigger a ResourceWarning in some[39;00m
[1;32m     57[0m [38;5;66;03m# cases, and look like a memory leak in others.[39;00m
[1;32m     58[0m [38;5;28;01mwith[39;00m sessions[38;5;241m.[39mSession() [38;5;28;01mas[39;00m session:
[0;32m---> 59[0m     [38;5;28;01mreturn[39;00m session[38;5;241m.[39mrequest(method[38;5;241m=[39mmethod, url[38;5;241m=[39murl, [38;5;241m*[39m[38;5;241m*[39mkwargs)

File [0;32m~/anaconda3/lib/python3.11/site-packages/requests/sessions.py:589[0m, in [0;36mSession.request[0;34m(self, method, url, params, data, headers, cookies, files, auth, timeout, allow_redirects, proxies, hooks, stream, verify, cert, json)[0m
[1;32m    584[0m send_kwargs [38;5;241m=[39m {
[1;32m    585[0m     [38;5;124m"[39m[38;5;124mtimeout[39m[38;5;124m"[39m: timeout,
[1;32m    586[0m     [38;5;124m"[39m[38;5;124mallow_redirects[39m[38;5;124m"[39m: allow_redirects,
[1;32m    587[0m }
[1;32m    588[0m send_kwargs[38;5;241m.[39mupdate(settings)
[0;32m--> 589[0m resp [38;5;241m=[39m [38;5;28mself[39m[38;5;241m.[39msend(prep, [38;5;241m*[39m[38;5;241m*[39msend_kwargs)
[1;32m    591[0m [38;5;28;01mreturn[39;00m resp

File [0;32m~/anaconda3/lib/python3.11/site-packages/requests/sessions.py:703[0m, in [0;36mSession.send[0;34m(self, request, **kwargs)[0m
[1;32m    700[0m start [38;5;241m=[39m preferred_clock()
[1;32m    702[0m [38;5;66;03m# Send the request[39;00m
[0;32m--> 703[0m r [38;5;241m=[39m adapter[38;5;241m.[39msend(request, [38;5;241m*[39m[38;5;241m*[39mkwargs)
[1;32m    705[0m [38;5;66;03m# Total elapsed time of the request (approximately)[39;00m
[1;32m    706[0m elapsed [38;5;241m=[39m preferred_clock() [38;5;241m-[39m start

File [0;32m~/anaconda3/lib/python3.11/site-packages/requests/adapters.py:519[0m, in [0;36mHTTPAdapter.send[0;34m(self, request, stream, timeout, verify, cert, proxies)[0m
[1;32m    515[0m     [38;5;28;01mif[39;00m [38;5;28misinstance[39m(e[38;5;241m.[39mreason, _SSLError):
[1;32m    516[0m         [38;5;66;03m# This branch is for urllib3 v1.22 and later.[39;00m
[1;32m    517[0m         [38;5;28;01mraise[39;00m SSLError(e, request[38;5;241m=[39mrequest)
[0;32m--> 519[0m     [38;5;28;01mraise[39;00m [38;5;167;01mConnectionError[39;00m(e, request[38;5;241m=[39mrequest)
[1;32m    521[0m [38;5;28;01mexcept[39;00m ClosedPoolError [38;5;28;01mas[39;00m e:
[1;32m    522[0m     [38;5;28;01mraise[39;00m [38;5;167;01mConnectionError[39;00m(e, request[38;5;241m=[39mrequest)

[0;31mConnectionError[0m: HTTPConnectionPool(host='localhost', port=8551): Max retries exceeded with url: / (Caused by NewConnectionError('<urllib3.connection.HTTPConnection object at 0x117cadf50>: Failed to establish a new connection: [Errno 61] Connection refused'))
ConnectionError: HTTPConnectionPool(host='localhost', port=8551): Max retries exceeded with url: / (Caused by NewConnectionError('<urllib3.connection.HTTPConnection object at 0x117cadf50>: Failed to establish a new connection: [Errno 61] Connection refused'))

